Workbook

Sheet lookup tables
B2: Country | C2: Fertility | D2: ISO-code | F2: Country | G2: Urbanization rate | H2: ISO-code | J2: Country | K2: Suicide rate | L2: ISO-code | N2: Country | O2: Sex-ratio | P2: ISO-code | R2: Country | S2: Population growth | T2: ISO-code | V2: Country | W2: Median age | X2: ISO-code | Z2: Country | AA2: Meat consumption | AB2: ISO-code | AD2: Country | AE2: Life expectancy | AF2: ISO-code | AH2: Country | AI2: Male Height in Cm | AJ2: Female Height in Cm | AK2: Male Height in Ft | AL2: Female Height in Ft | AN2: Country | AO2: GDP per capita | AP2: ISO-code
B3: Afghanistan | C3: 4.5 | D3: AFG | F3: Afghanistan | G3: 26 | H3: AFG | J3: Afghanistan | K3: 6.4 | L3: AFG | N3: Afghanistan | O3: 1.03 | P3: AFG | R3: Afghanistan | S3: 2.41 | T3: AFG | V3: Afghanistan | W3: 27.4 | X3: AFG | Z3: Afghanistan | AA3: 17.3 | AB3: AFG | AD3: Afghanistan | AE3: 64.5 | AF3: AFG | AH3: Afghanistan | AI3: 168.5 | AJ3: 156.11 | AK3: 5.53 | AL3: 5.12 | AN3: Afghanistan | AO3: 2182 | AP3: AFG
B4: Albania | C4: 1.6 | D4: ALB | F4: Albania | G4: 62.1 | H4: ALB | J4: Albania | K4: 5.6 | L4: ALB | N4: Albania | O4: 0.98 | P4: ALB | R4: Albania | S4: 0.26 | T4: ALB | V4: Albania | W4: 32.9 | X4: ALB | Z4: Algeria | AA4: 18.3 | AB4: DZA | AD4: Algeria | AE4: 76.7 | AF4: DZA | AH4: Albania | AI4: 174.07 | AJ4: 162.23 | AK4: 5.71 | AL4: 5.32 | AN4: Albania | AO4: 14866 | AP4: ALB
B5: Algeria | C5: 3 | D5: DZA | F5: Algeria | G5: 73.7 | H5: DZA | J5: Algeria | K5: 3.3 | L5: DZA | N5: Algeria | O5: 1.03 | P5: DZA | R5: Algeria | S5: 1.89 | T5: DZA | V5: Algeria | W5: 28.1 | X5: DZA | Z5: American Samoa | AA5: 24.9 | AB5: ASM | AD5: Andorra | AE5: 81.8 | AF5: AND | AH5: Algeria | AI5: 175.04 | AJ5: 162.35 | AK5: 5.74 | AL5: 5.33 | AN5: Algeria | AO5: 16091 | AP5: DZA
B6: Andorra | C6: 1.3 | D6: AND | F6: American Samoa | G6: 87.2 | H6: ASM | J6: Angola | K6: 8.9 | L6: AGO | N6: American Samoa | O6: 1 | P6: ASM | R6: American Samoa | S6: -0.26 | T6: ASM | V6: American Samoa | W6: 25.5 | X6: ASM | Z6: Angola | AA6: 19 | AB6: AGO | AD6: Angola | AE6: 60.8 | AF6: AGO | AH6: American Samoa | AI6: 177.09 | AJ6: 167.55 | AK6: 5.81 | AL6: 5.5 | AN6: Angola | AO6: 6763 | AP6: AGO
B7: Angola | C7: 5.5 | D7: AGO | F7: Andorra | G7: 87.9 | H7: AND | J7: Antigua and Barbuda | K7: 0.5 | L7: ATG | N7: Andorra | O7: 1.06 | P7: AND | R7: Andorra | S7: 0.63 | T7: AND | V7: Andorra | W7: 44.3 | X7: AND | Z7: Antigua and Barbuda | AA7: 56 | AB7: ATG | AD7: Antigua and Barbuda | AE7: 76.9 | AF7: ATG | AH7: Andorra | AI7: 178.84 | AJ7: 165.53 | AK7: 5.87 | AL7: 5.43 | AN7: Antigua and Barbuda | AO7: 30593 | AP7: ATG
B8: Antigua and Barbuda | C8: 2 | D8: ATG | F8: Angola | G8: 66.8 | H8: AGO | J8: Argentina | K8: 9.1 | L8: ARG | N8: Angola | O8: 0.95 | P8: AGO | R8: Angola | S8: 3.12 | T8: AGO | V8: Angola | W8: 15.9 | X8: AGO | Z8: Argentina | AA8: 79.7 | AB8: ARG | AD8: Argentina | AE8: 76.5 | AF8: ARG | AH8: Angola | AI8: 168.46 | AJ8: 158.1 | AK8: 5.53 | AL8: 5.19 | AN8: Argentina | AO8: 19971 | AP8: ARG
B9: Argentina | C9: 2.3 | D9: ARG | F9: Anguilla | G9: 100 | H9: AIA | J9: Armenia | K9: 5.7 | L9: ARM | N9: Anguilla | O9: 0.9 | P9: AIA | R9: Antigua and Barbuda | S9: 1.03 | T9: ATG | V9: Anguilla | W9: 34.8 | X9: AIA | Z9: Armenia | AA9: 27.7 | AB9: ARM | AD9: Armenia | AE9: 74.9 | AF9: ARM | AH9: Antigua and Barbuda | AI9: 178.84 | AJ9: 165.72 | AK9: 5.87 | AL9: 5.44 | AN9: Armenia | AO9: 11845 | AP9: ARM
B10: Armenia | C10: 1.8 | D10: ARM | F10: Antigua and Barbuda | G10: 24.4 | H10: ATG | J10: Australia | K10: 11.7 | L10: AUS | N10: Antigua and Barbuda | O10: 0.89 | P10: ATG | R10: Argentina | S10: 0.88 | T10: ARG | V10: Antigua and Barbuda | W10: 31.9 | X10: ATG | Z10: Australia | AA10: 108.2 | AB10: AUS | AD10: Australia | AE10: 83.3 | AF10: AUS | AH10: Argentina | AI10: 174.76 | AJ10: 161.22 | AK10: 5.73 | AL10: 5.29 | AN10: Australia | AO10: 54799 | AP10: AUS
B11: Aruba | C11: 1.9 | D11: ABW | F11: Argentina | G11: 92.1 | H11: ARG | J11: Austria | K11: 11.4 | L11: AUT | N11: Argentina | O11: 0.98 | P11: ARG | R11: Armenia | S11: 0.17 | T11: ARM | V11: Argentina | W11: 31.7 | X11: ARG | Z11: Austria | AA11: 94.1 | AB11: AUT | AD11: Austria | AE11: 81.4 | AF11: AUT | AH11: Armenia | AI11: 173.67 | AJ11: 159.85 | AK11: 5.7 | AL11: 5.24 | AN11: Austria | AO11: 55171 | AP11: AUT
B12: Australia | C12: 1.7 | D12: AUS | F12: Armenia | G12: 63.3 | H12: ARM | J12: Azerbaijan | K12: 2.6 | L12: AZE | N12: Armenia | O12: 0.95 | P12: ARM | R12: Aruba | S12: 0.44 | T12: ABW | V12: Armenia | W12: 35.1 | X12: ARM | Z12: Azerbaijan | AA12: 15.9 | AB12: AZE | AD12: Azerbaijan | AE12: 72.9 | AF12: AZE | AH12: Australia | AI12: 178.77 | AJ12: 164.67 | AK12: 5.87 | AL12: 5.4 | AN12: Azerbaijan | AO12: 19156 | AP12: AZE
B13: Austria | C13: 1.5 | D13: AUT | F13: Aruba | G13: 43.7 | H13: ABW | J13: Bahrain | K13: 5.7 | L13: BHR | N13: Aruba | O13: 0.9 | P13: ABW | R13: Australia | S13: 1.6 | T13: AUS | V13: Aruba | W13: 39.3 | X13: ABW | Z13: Bahrain | AA13: 70.7 | AB13: BHR | AD13: Bahrain | AE13: 77.2 | AF13: BHR | AH13: Austria | AI13: 178.52 | AJ13: 166.93 | AK13: 5.86 | AL13: 5.48 | AN13: Bahrain | AO13: 51991 | AP13: BHR
B14: Azerbaijan | C14: 1.7 | D14: AZE | F14: Australia | G14: 86.2 | H14: AUS | J14: Bangladesh | K14: 6.1 | L14: BGD | N14: Australia | O14: 0.99 | P14: AUS | R14: Austria | S14: 0.46 | T14: AUT | V14: Australia | W14: 38.7 | X14: AUS | Z14: Bangladesh | AA14: 3.1 | AB14: BGD | AD14: Bangladesh | AE14: 72.3 | AF14: BGD | AH14: Azerbaijan | AI14: 174 | AJ14: 161.37 | AK14: 5.71 | AL14: 5.29 | AN14: Bangladesh | AO14: 5453 | AP14: BGD
... B30: Burkina Faso | C30: 5.2 | D30: BFA | F30: Brunei | G30: 78.3 | H30: BRN | J30: Cameroon | K30: 19.5 | L30: CMR | N30: Brazil | O30: 0.97 | P30: BRA | R30: Bulgaria | S30: -0.6 | T30: BGR | V30: Brazil | W30: 32.6 | X30: BRA | Z30: Canada | AA30: 108.1 | AB30: CAN | AD30: Cameroon | AE30: 58.9 | AF30: CMR | AH30: Bulgaria | AI30: 174.17 | AJ30: 164.58 | AK30: 5.71 | AL30: 5.4 | AN30: Cameroon | AO30: 4099 | AP30: CMR
B31: Burundi | C31: 5.4 | D31: BDI | F31: Bulgaria | G31: 75.7 | H31: BGR | J31: Canada | K31: 10.4 | L31: CAN | N31: Brunei | O31: 0.96 | P31: BRN | R31: Burkina Faso | S31: 2.86 | T31: BFA | V31: British Virgin Islands | W31: 36.5 | Z31: Cape Verde | AA31: 26.3 | AB31: CPV | AD31: Canada | AE31: 82.3 | AF31: CAN | AH31: Burkina Faso | AI31: 171.89 | AJ31: 161.33 | AK31: 5.64 | AL31: 5.29 | AN31: Canada | AO31: 52144 | AP31: CAN
B32: Cambodia | C32: 2.5 | D32: KHM | F32: Burkina Faso | G32: 30.6 | H32: BFA | J32: Cape Verde | K32: 15.1 | L32: CPV | N32: Bulgaria | O32: 0.95 | P32: BGR | R32: Burundi | S32: 3.19 | T32: BDI | V32: Brunei | W32: 30.2 | X32: BRN | Z32: Central African Republic | AA32: 28 | AB32: CAF | AD32: Cape Verde | AE32: 72.8 | AF32: CPV | AH32: Burundi | AI32: 167.34 | AJ32: 155.08 | AK32: 5.49 | AL32: 5.09 | AN32: Cape Verde | AO32: 8716 | AP32: CPV
B33: Cameroon | C33: 4.6 | D33: CMR | F33: Burundi | G33: 13.7 | H33: BDI | J33: Central African Republic | K33: 11.6 | L33: CAF | N33: Burkina Faso | O33: 0.96 | P33: BFA | R33: Cambodia | S33: 1.76 | T33: KHM | V33: Bulgaria | W33: 42.7 | X33: BGR | Z33: Chad | AA33: 14.3 | AB33: TCD | AD33: Central African Republic | AE33: 52.8 | AF33: CAF | AH33: Cambodia | AI33: 165.35 | AJ33: 154.75 | AK33: 5.42 | AL33: 5.08 | AN33: Central African Republic | AO33: 864 | AP33: CAF
B34: Canada | C34: 1.5 | D34: CAN | F34: Cambodia | G34: 24.2 | H34: KHM | J34: Chad | K34: 15.5 | L34: TCD | N34: Burundi | O34: 0.99 | P34: BDI | R34: Cameroon | S34: 2.54 | T34: CMR | V34: Burkina Faso | W34: 17.3 | X34: BFA | Z34: Chile | AA34: 66.4 | AB34: CHL | AD34: Chad | AE34: 54 | AF34: TCD | AH34: Cameroon | AI34: 172.13 | AJ34: 160.41 | AK34: 5.65 | AL34: 5.26 | AN34: Chad | AO34: 2603 | AP34: TCD
B35: Cape Verde | C35: 2.3 | D35: CPV | F35: Cameroon | G35: 57.6 | H35: CMR | J35: Chile | K35: 9.7 | L35: CHL | N35: Cambodia | O35: 0.95 | P35: KHM | R35: Canada | S35: 1.14 | T35: CAN | V35: Burundi | W35: 17 | X35: BDI | Z35: China | AA35: 52.4 | AB35: CHN | AD35: Chile | AE35: 80 | AF35: CHL | AH35: Canada | AI35: 178.75 | AJ35: 164.73 | AK35: 5.86 | AL35: 5.4 | AN35: Chile | AO35: 27150 | AP35: CHL
B36: Central African Republic | C36: 4.7 | D36: CAF | F36: Canada | G36: 81.6 | H36: CAN | J36: China | K36: 8 | L36: CHN | N36: Cameroon | O36: 0.99 | P36: CMR | R36: Cape Verde | S36: 0.78 | T36: CPV | V36: Cape Verde | W36: 25.4 | X36: CPV | Z36: Colombia | AA36: 33.9 | AB36: COL | AD36: China | AE36: 76.7 | AF36: CHN | AH36: Central African Republic | AI36: 169.01 | AJ36: 159.65 | AK36: 5.54 | AL36: 5.24 | AN36: China | AO36: 20984 | AP36: CHN
B37: Chad | C37: 5.7 | D37: TCD | F37: Cape Verde | G37: 66.7 | H37: CPV | J37: Colombia | K37: 7 | L37: COL | N37: Canada | O37: 0.98 | P37: CAN | R37: Cayman Islands | S37: 1.7 | T37: CYM | V37: Cambodia | W37: 25.3 | X37: KHM | Z37: Comoros | AA37: 7.6 | AB37: COM | AD37: Colombia | AE37: 77.1 | AF37: COL | AH37: Chad | AI37: 171.84 | AJ37: 162.12 | AK37: 5.64 | AL37: 5.32 | AN37: Colombia | AO37: 16265 | AP37: COL
B38: Chile | C38: 1.6 | D38: CHL | F38: Cayman Islands | G38: 100 | H38: CYM | J38: Comoros | K38: 11.1 | L38: COM | N38: Cape Verde | O38: 0.95 | P38: CPV | R38: Central African Republic | S38: 1.99 | T38: CAF | V38: Cameroon | W38: 18.5 | X38: CMR | Z38: Costa Rica | AA38: 40.4 | AB38: CRI | AD38: Comoros | AE38: 64.1 | AF38: COM | AH38: Chile | AI38: 172.88 | AJ38: 159.42 | AK38: 5.67 | AL38: 5.23 | AN38: Comoros | AO38: 2898 | AP38: COM
B39: China | C39: 1.7 | D39: CHN | F39: Central African Republic | G39: 42.2 | H39: CAF | J39: Costa Rica | K39: 7.5 | L39: CRI | N39: Cayman Islands | O39: 0.95 | P39: CYM | R39: Chad | S39: 3 | T39: TCD | V39: Canada | W39: 42.2 | X39: CAN | Z39: Croatia | AA39: 49.9 | AB39: HRV | AD39: Costa Rica | AE39: 80.1 | AF39: CRI | AH39: China | AI39: 175.66 | AJ39: 163.46 | AK39: 5.76 | AL39: 5.36 | AN39: Costa Rica | AO39: 18651 | AP39: CRI
B40: Colombia | C40: 1.8 | D40: COL | F40: Chad | G40: 23.5 | H40: TCD | J40: Croatia | K40: 11.5 | L40: HRV | N40: Central African Republic | O40: 0.99 | P40: CAF | R40: Chile | S40: 0.9 | T40: CHL | V40: Cayman Islands | W40: 40 | X40: CYM | Z40: Cuba | AA40: 32.2 | AB40: CUB | AD40: Croatia | AE40: 78.3 | AF40: HRV | AH40: Colombia | AI40: 171.85 | AJ40: 157.96 | AK40: 5.64 | AL40: 5.18 | AN40: Croatia | AO40: 29207 | AP40: HRV
B41: Comoros | C41: 4.2 | D41: COM | F41: Chile | G41: 87.7 | H41: CHL | J41: Cuba | K41: 10.1 | L41: CUB | N41: Chad | O41: 0.98 | P41: TCD | R41: China | S41: 0.49 | T41: CHN | V41: Central African Republic | W41: 19.7 | X41: CAF | Z41: Cyprus | AA41: 131.3 | AB41: CYP | AD41: Cuba | AE41: 78.6 | AF41: CUB | AH41: Comoros | AI41: 167.72 | AJ41: 156.54 | AK41: 5.5 | AL41: 5.14 | AN41: Cuba | AO41: 8822 | AP41: CUB
B42: Costa Rica | C42: 1.8 | D42: CRI | F42: China | G42: 61.4 | H42: CHN | J42: Cyprus | K42: 4.5 | L42: CYP | N42: Chile | O42: 0.97 | P42: CHL | R42: Colombia | S42: 1.32 | T42: COL | V42: Chad | W42: 17.8 | X42: TCD | Z42: Czech Republic | AA42: 77.3 | AB42: CZE | AD42: Cyprus | AE42: 80.8 | AF42: CYP | AH42: Cook Islands | AI42: 178.32 | AJ42: 167.31 | AK42: 5.85 | AL42: 5.49 | AN42: Cyprus | AO42: 42956 | AP42: CYP
B43: Croatia | C43: 1.5 | D43: HRV | F43: Colombia | G43: 81.4 | H43: COL | J43: Czech Republic | K43: 10.5 | L43: CZE | N43: China | O43: 1.06 | P43: CHN | R43: Comoros | S43: 2.44 | T43: COM | V43: Chile | W43: 34.4 | X43: CHL | Z43: Democratic Republic of the Congo | AA43: 4.8 | AB43: COD | AD43: Czech Republic | AE43: 79.2 | AF43: CZE | AH43: Costa Rica | AI43: 174.04 | AJ43: 160.36 | AK43: 5.71 | AL43: 5.26 | AN43: Czech Republic | AO43: 40585 | AP43: CZE
... B56: El Salvador | C56: 2 | D56: SLV | F56: Dominican Republic | G56: 82.5 | H56: DOM | J56: Ethiopia | K56: 11.4 | L56: ETH | N56: Djibouti | O56: 0.83 | P56: DJI | R56: Ecuador | S56: 1.6 | T56: ECU | V56: Czech Republic | W56: 42.1 | X56: CZE | Z56: Finland | AA56: 67.4 | AB56: FIN | AD56: Ethiopia | AE56: 66.2 | AF56: ETH | AH56: Equatorial Guinea | AI56: 168.18 | AJ56: 158.05 | AK56: 5.52 | AL56: 5.19 | AN56: Eswatini | AO56: 11139 | AP56: SWZ
B57: Equatorial Guinea | C57: 4.5 | D57: GNQ | F57: East Timor | G57: 31.3 | H57: TLS | J57: Fiji | K57: 5.5 | L57: FJI | N57: Dominica | O57: 1.02 | P57: DMA | R57: Egypt | S57: 1.66 | T57: EGY | V57: Denmark | W57: 42.2 | X57: DNK | Z57: FR Yugoslavia | AA57: 77.6 | AD57: Fiji | AE57: 67.3 | AF57: FJI | AH57: Eritrea | AI57: 170.6 | AJ57: 157.58 | AK57: 5.6 | AL57: 5.17 | AN57: Ethiopia | AO57: 2702 | AP57: ETH
B58: Eritrea | C58: 4.1 | D58: ERI | F58: Ecuador | G58: 64.2 | H58: ECU | J58: Finland | K58: 11.7 | L58: FIN | N58: Dominican Republic | O58: 1.02 | P58: DOM | R58: El Salvador | S58: 0.66 | T58: SLV | V58: Djibouti | W58: 23.9 | X58: DJI | Z58: France | AA58: 101.1 | AB58: FRA | AD58: Finland | AE58: 81.7 | AF58: FIN | AH58: Estonia | AI58: 182.79 | AJ58: 168.66 | AK58: 6 | AL58: 5.53 | AN58: Fiji | AO58: 12689 | AP58: FJI
B59: Estonia | C59: 1.7 | D59: EST | F59: Egypt | G59: 42.8 | H59: EGY | J59: France | K59: 12.1 | L59: FRA | N59: Ecuador | O59: 0.99 | P59: ECU | R59: Equatorial Guinea | S59: 2.8 | T59: GNQ | V59: Dominica | W59: 33.5 | X59: DMA | Z59: French Guiana | AA59: 13.2 | AB59: GUF | AD59: France | AE59: 82.5 | AF59: FRA | AH59: Eswatini | AI59: 169.41 | AJ59: 158.92 | AK59: 5.56 | AL59: 5.21 | AN59: Finland | AO59: 49548 | AP59: FIN
B60: Eswatini | C60: 3 | D60: SWZ | F60: El Salvador | G60: 73.4 | H60: SLV | J60: Gabon | K60: 9.6 | L60: GAB | N60: Egypt | O60: 1.05 | P60: EGY | R60: Eritrea | S60: 3.28 | T60: ERI | V60: Dominican Republic | W60: 28.1 | X60: DOM | Z60: French Polynesia | AA60: 112.2 | AB60: PYF | AD60: Gabon | AE60: 66.2 | AF60: GAB | AH60: Ethiopia | AI60: 168.84 | AJ60: 157.15 | AK60: 5.54 | AL60: 5.16 | AN60: France | AO60: 48640 | AP60: FRA
B61: Ethiopia | C61: 4.2 | D61: ETH | F61: Equatorial Guinea | G61: 73.1 | H61: GNQ | J61: Georgia | K61: 6.7 | L61: GEO | N61: El Salvador | O61: 0.92 | P61: SLV | R61: Estonia | S61: -0.04 | T61: EST | V61: Ecuador | W61: 27.7 | X61: ECU | Z61: Gabon | AA61: 46 | AB61: GAB | AD61: Georgia | AE61: 73.6 | AF61: GEO | AH61: Fiji | AI61: 173.98 | AJ61: 164.28 | AK61: 5.71 | AL61: 5.39 | AN61: Gabon | AO61: 19839 | AP61: GAB
B62: Faroe Islands | C62: 2.5 | D62: FRO | F62: Eritrea | G62: 41.3 | H62: ERI | J62: Germany | K62: 9.1 | L62: DEU | N62: Equatorial Guinea | O62: 1 | P62: GNQ | R62: Eswatini | S62: 1.54 | T62: SWZ | V62: Egypt | W62: 23.9 | X62: EGY | Z62: Georgia | AA62: 26 | AB62: GEO | AD62: Germany | AE62: 81.2 | AF62: DEU | AH62: Finland | AI62: 180.57 | AJ62: 166.48 | AK62: 5.92 | AL62: 5.46 | AN62: Georgia | AO62: 13200 | AP62: GEO
B63: Fiji | C63: 2.8 | D63: FJI | F63: Estonia | G63: 69.2 | H63: EST | J63: Ghana | K63: 8.7 | L63: GHA | N63: Eritrea | O63: 0.97 | P63: ERI | R63: Ethiopia | S63: 2.58 | T63: ETH | V63: El Salvador | W63: 27.1 | X63: SLV | Z63: Germany | AA63: 82.1 | AB63: DEU | AD63: Ghana | AE63: 63.8 | AF63: GHA | AH63: France | AI63: 178.6 | AJ63: 164.49 | AK63: 5.86 | AL63: 5.4 | AN63: Germany | AO63: 55306 | AP63: DEU
B64: Finland | C64: 1.4 | D64: FIN | F64: Eswatini | G64: 24.2 | H64: SWZ | J64: Greece | K64: 3.8 | L64: GRC | N64: Estonia | O64: 0.88 | P64: EST | R64: Fiji | S64: 0.78 | T64: FJI | V64: Equatorial Guinea | W64: 19.8 | X64: GNQ | Z64: Ghana | AA64: 9.9 | AB64: GHA | AD64: Greece | AE64: 82.1 | AF64: GRC | AH64: French Polynesia | AI64: 178.32 | AJ64: 166.52 | AK64: 5.85 | AL64: 5.46 | AN64: Ghana | AO64: 7343 | AP64: GHA
B65: France | C65: 1.9 | D65: FRA | F65: Ethiopia | G65: 21.7 | H65: ETH | J65: Greenland | K65: 11.3 | L65: GRL | N65: Eswatini | O65: 0.9 | P65: SWZ | R65: Finland | S65: 0.48 | T65: FIN | V65: Eritrea | W65: 19.7 | X65: ERI | Z65: Greece | AA65: 78.7 | AB65: GRC | AD65: Greenland | AE65: 71.25 | AF65: GRL | AH65: Gabon | AI65: 170.48 | AJ65: 160.05 | AK65: 5.59 | AL65: 5.25 | AN65: Greece | AO65: 31616 | AP65: GRC
B66: French Polynesia | C66: 1.9 | D66: PYF | F66: Faroe Islands | G66: 42.4 | H66: FRO | J66: Grenada | K66: 1.7 | L66: GRD | N66: Ethiopia | O66: 1 | P66: ETH | R66: France | S66: 0.5 | T66: FRA | V66: Estonia | W66: 42.7 | X66: EST | Z66: Greenland | AA66: 63.4 | AB66: GRL | AD66: Grenada | AE66: 72.4 | AF66: GRD | AH66: Gambia | AI66: 168.36 | AJ66: 161.73 | AK66: 5.52 | AL66: 5.31 | AN66: Greenland | AO66: 48182 | AP66: GRL
B67: Gabon | C67: 4 | D67: GAB | F67: Fiji | G67: 57.2 | H67: FJI | J67: Guatemala | K67: 2.9 | L67: GTM | N67: Faroe Islands | O67: 1.08 | P67: FRO | R67: French Polynesia | S67: 1.08 | T67: PYF | V67: Eswatini | W67: 21.7 | X67: SWZ | Z67: Grenada | AA67: 97 | AB67: GRD | AD67: Guatemala | AE67: 74.1 | AF67: GTM | AH67: Georgia | AI67: 175.98 | AJ67: 163.24 | AK67: 5.77 | AL67: 5.36 | AN67: Grenada | AO67: 17434 | AP67: GRD
B68: Georgia | C68: 2.1 | D68: GEO | F68: Finland | G68: 85.5 | H68: FIN | J68: Guinea | K68: 10.5 | L68: GIN | N68: Fiji | O68: 1.03 | P68: FJI | R68: Gabon | S68: 2.39 | T68: GAB | V68: Ethiopia | W68: 17.9 | X68: ETH | Z68: Guadeloupe | AA68: 12.7 | AB68: GLP | AD68: Guinea | AE68: 61.2 | AF68: GIN | AH68: Germany | AI68: 180.28 | AJ68: 166.18 | AK68: 5.91 | AL68: 5.45 | AN68: Guatemala | AO68: 9009 | AP68: GTM
...

Sheet master table
B2: Country | C2: Fertility | D2: Urbanization Rate | E2: Suicide rate | F2: Sex-ratio | G2: Population growth | H2: Median age | I2: Meat consumption | J2: Life expectancy | K2: Male Height in Cm | L2: Female Height in Cm | M2: GDP per capita
B3: Afghanistan | C3: =VLOOKUP('master table'!B3,Table1[#All], 2,FALSE) -> 4.5 | D3: =VLOOKUP('master table'!B3,Table2[#All], 2,FALSE) -> 26 | E3: =VLOOKUP('master table'!B3,Table3[#All], 2,FALSE) -> 6.4 | F3: =VLOOKUP('master table'!B3,Table4[#All], 2,FALSE) -> 1.03 | G3: =VLOOKUP('master table'!B3,Table5[#All], 2,FALSE) -> 2.41 | H3: =VLOOKUP('master table'!B3,Table6[#All], 2,FALSE) -> 27.4 | I3: =VLOOKUP('master table'!B3,Table7[#All], 2,FALSE) -> 17.3 | J3: =VLOOKUP('master table'!B3,Table8[#All], 2,FALSE) -> 64.5 | K3: =VLOOKUP('master table'!B3,Table9[#All], 2,FALSE) -> 168.5 | L3: =VLOOKUP('master table'!B3,Table9[#All], 3,FALSE) -> 156.11 | M3: =VLOOKUP('master table'!B3,Table10[#All], 2,FALSE) -> 2182
B4: Algeria | C4: =VLOOKUP('master table'!B4,Table1[#All], 2,FALSE) -> 3 | D4: =VLOOKUP('master table'!B4,Table2[#All], 2,FALSE) -> 73.7 | E4: =VLOOKUP('master table'!B4,Table3[#All], 2,FALSE) -> 3.3 | F4: =VLOOKUP('master table'!B4,Table4[#All], 2,FALSE) -> 1.03 | G4: =VLOOKUP('master table'!B4,Table5[#All], 2,FALSE) -> 1.89 | H4: =VLOOKUP('master table'!B4,Table6[#All], 2,FALSE) -> 28.1 | I4: =VLOOKUP('master table'!B4,Table7[#All], 2,FALSE) -> 18.3 | J4: =VLOOKUP('master table'!B4,Table8[#All], 2,FALSE) -> 76.7 | K4: =VLOOKUP('master table'!B4,Table9[#All], 2,FALSE) -> 175.04 | L4: =VLOOKUP('master table'!B4,Table9[#All], 3,FALSE) -> 162.35 | M4: =VLOOKUP('master table'!B4,Table10[#All], 2,FALSE) -> 16091
B5: Angola | C5: =VLOOKUP('master table'!B5,Table1[#All], 2,FALSE) -> 5.5 | D5: =VLOOKUP('master table'!B5,Table2[#All], 2,FALSE) -> 66.8 | E5: =VLOOKUP('master table'!B5,Table3[#All], 2,FALSE) -> 8.9 | F5: =VLOOKUP('master table'!B5,Table4[#All], 2,FALSE) -> 0.95 | G5: =VLOOKUP('master table'!B5,Table5[#All], 2,FALSE) -> 3.12 | H5: =VLOOKUP('master table'!B5,Table6[#All], 2,FALSE) -> 15.9 | I5: =VLOOKUP('master table'!B5,Table7[#All], 2,FALSE) -> 19 | J5: =VLOOKUP('master table'!B5,Table8[#All], 2,FALSE) -> 60.8 | K5: =VLOOKUP('master table'!B5,Table9[#All], 2,FALSE) -> 168.46 | L5: =VLOOKUP('master table'!B5,Table9[#All], 3,FALSE) -> 158.1 | M5: =VLOOKUP('master table'!B5,Table10[#All], 2,FALSE) -> 6763
B6: Antigua and Barbuda | C6: =VLOOKUP('master table'!B6,Table1[#All], 2,FALSE) -> 2 | D6: =VLOOKUP('master table'!B6,Table2[#All], 2,FALSE) -> 24.4 | E6: =VLOOKUP('master table'!B6,Table3[#All], 2,FALSE) -> 0.5 | F6: =VLOOKUP('master table'!B6,Table4[#All], 2,FALSE) -> 0.89 | G6: =VLOOKUP('master table'!B6,Table5[#All], 2,FALSE) -> 1.03 | H6: =VLOOKUP('master table'!B6,Table6[#All], 2,FALSE) -> 31.9 | I6: =VLOOKUP('master table'!B6,Table7[#All], 2,FALSE) -> 56 | J6: =VLOOKUP('master table'!B6,Table8[#All], 2,FALSE) -> 76.9 | K6: =VLOOKUP('master table'!B6,Table9[#All], 2,FALSE) -> 178.84 | L6: =VLOOKUP('master table'!B6,Table9[#All], 3,FALSE) -> 165.72 | M6: =VLOOKUP('master table'!B6,Table10[#All], 2,FALSE) -> 30593
B7: Argentina | C7: =VLOOKUP('master table'!B7,Table1[#All], 2,FALSE) -> 2.3 | D7: =VLOOKUP('master table'!B7,Table2[#All], 2,FALSE) -> 92.1 | E7: =VLOOKUP('master table'!B7,Table3[#All], 2,FALSE) -> 9.1 | F7: =VLOOKUP('master table'!B7,Table4[#All], 2,FALSE) -> 0.98 | G7: =VLOOKUP('master table'!B7,Table5[#All], 2,FALSE) -> 0.88 | H7: =VLOOKUP('master table'!B7,Table6[#All], 2,FALSE) -> 31.7 | I7: =VLOOKUP('master table'!B7,Table7[#All], 2,FALSE) -> 79.7 | J7: =VLOOKUP('master table'!B7,Table8[#All], 2,FALSE) -> 76.5 | K7: =VLOOKUP('master table'!B7,Table9[#All], 2,FALSE) -> 174.76 | L7: =VLOOKUP('master table'!B7,Table9[#All], 3,FALSE) -> 161.22 | M7: =VLOOKUP('master table'!B7,Table10[#All], 2,FALSE) -> 19971
B8: Armenia | C8: =VLOOKUP('master table'!B8,Table1[#All], 2,FALSE) -> 1.8 | D8: =VLOOKUP('master table'!B8,Table2[#All], 2,FALSE) -> 63.3 | E8: =VLOOKUP('master table'!B8,Table3[#All], 2,FALSE) -> 5.7 | F8: =VLOOKUP('master table'!B8,Table4[#All], 2,FALSE) -> 0.95 | G8: =VLOOKUP('master table'!B8,Table5[#All], 2,FALSE) -> 0.17 | H8: =VLOOKUP('master table'!B8,Table6[#All], 2,FALSE) -> 35.1 | I8: =VLOOKUP('master table'!B8,Table7[#All], 2,FALSE) -> 27.7 | J8: =VLOOKUP('master table'!B8,Table8[#All], 2,FALSE) -> 74.9 | K8: =VLOOKUP('master table'!B8,Table9[#All], 2,FALSE) -> 173.67 | L8: =VLOOKUP('master table'!B8,Table9[#All], 3,FALSE) -> 159.85 | M8: =VLOOKUP('master table'!B8,Table10[#All], 2,FALSE) -> 11845
B9: Australia | C9: =VLOOKUP('master table'!B9,Table1[#All], 2,FALSE) -> 1.7 | D9: =VLOOKUP('master table'!B9,Table2[#All], 2,FALSE) -> 86.2 | E9: =VLOOKUP('master table'!B9,Table3[#All], 2,FALSE) -> 11.7 | F9: =VLOOKUP('master table'!B9,Table4[#All], 2,FALSE) -> 0.99 | G9: =VLOOKUP('master table'!B9,Table5[#All], 2,FALSE) -> 1.6 | H9: =VLOOKUP('master table'!B9,Table6[#All], 2,FALSE) -> 38.7 | I9: =VLOOKUP('master table'!B9,Table7[#All], 2,FALSE) -> 108.2 | J9: =VLOOKUP('master table'!B9,Table8[#All], 2,FALSE) -> 83.3 | K9: =VLOOKUP('master table'!B9,Table9[#All], 2,FALSE) -> 178.77 | L9: =VLOOKUP('master table'!B9,Table9[#All], 3,FALSE) -> 164.67 | M9: =VLOOKUP('master table'!B9,Table10[#All], 2,FALSE) -> 54799
B10: Austria | C10: =VLOOKUP('master table'!B10,Table1[#All], 2,FALSE) -> 1.5 | D10: =VLOOKUP('master table'!B10,Table2[#All], 2,FALSE) -> 58.7 | E10: =VLOOKUP('master table'!B10,Table3[#All], 2,FALSE) -> 11.4 | F10: =VLOOKUP('master table'!B10,Table4[#All], 2,FALSE) -> 0.96 | G10: =VLOOKUP('master table'!B10,Table5[#All], 2,FALSE) -> 0.46 | H10: =VLOOKUP('master table'!B10,Table6[#All], 2,FALSE) -> 44 | I10: =VLOOKUP('master table'!B10,Table7[#All], 2,FALSE) -> 94.1 | J10: =VLOOKUP('master table'!B10,Table8[#All], 2,FALSE) -> 81.4 | K10: =VLOOKUP('master table'!B10,Table9[#All], 2,FALSE) -> 178.52 | L10: =VLOOKUP('master table'!B10,Table9[#All], 3,FALSE) -> 166.93 | M10: =VLOOKUP('master table'!B10,Table10[#All], 2,FALSE) -> 55171
B11: Azerbaijan | C11: =VLOOKUP('master table'!B11,Table1[#All], 2,FALSE) -> 1.7 | D11: =VLOOKUP('master table'!B11,Table2[#All], 2,FALSE) -> 56.4 | E11: =VLOOKUP('master table'!B11,Table3[#All], 2,FALSE) -> 2.6 | F11: =VLOOKUP('master table'!B11,Table4[#All], 2,FALSE) -> 0.98 | G11: =VLOOKUP('master table'!B11,Table5[#All], 2,FALSE) -> 1.35 | H11: =VLOOKUP('master table'!B11,Table6[#All], 2,FALSE) -> 32.3 | I11: =VLOOKUP('master table'!B11,Table7[#All], 2,FALSE) -> 15.9 | J11: =VLOOKUP('master table'!B11,Table8[#All], 2,FALSE) -> 72.9 | K11: =VLOOKUP('master table'!B11,Table9[#All], 2,FALSE) -> 174 | L11: =VLOOKUP('master table'!B11,Table9[#All], 3,FALSE) -> 161.37 | M11: =VLOOKUP('master table'!B11,Table10[#All], 2,FALSE) -> 19156
B12: Bahrain | C12: =VLOOKUP('master table'!B12,Table1[#All], 2,FALSE) -> 2 | D12: =VLOOKUP('master table'!B12,Table2[#All], 2,FALSE) -> 89.5 | E12: =VLOOKUP('master table'!B12,Table3[#All], 2,FALSE) -> 5.7 | F12: =VLOOKUP('master table'!B12,Table4[#All], 2,FALSE) -> 1.53 | G12: =VLOOKUP('master table'!B12,Table5[#All], 2,FALSE) -> 1.92 | H12: =VLOOKUP('master table'!B12,Table6[#All], 2,FALSE) -> 32.3 | I12: =VLOOKUP('master table'!B12,Table7[#All], 2,FALSE) -> 70.7 | J12: =VLOOKUP('master table'!B12,Table8[#All], 2,FALSE) -> 77.2 | K12: =VLOOKUP('master table'!B12,Table9[#All], 2,FALSE) -> 172.76 | L12: =VLOOKUP('master table'!B12,Table9[#All], 3,FALSE) -> 158.29 | M12: =VLOOKUP('master table'!B12,Table10[#All], 2,FALSE) -> 51991
B13: Bangladesh | C13: =VLOOKUP('master table'!B13,Table1[#All], 2,FALSE) -> 2 | D13: =VLOOKUP('master table'!B13,Table2[#All], 2,FALSE) -> 38.2 | E13: =VLOOKUP('master table'!B13,Table3[#All], 2,FALSE) -> 6.1 | F13: =VLOOKUP('master table'!B13,Table4[#All], 2,FALSE) -> 0.97 | G13: =VLOOKUP('master table'!B13,Table5[#All], 2,FALSE) -> 1.19 | H13: =VLOOKUP('master table'!B13,Table6[#All], 2,FALSE) -> 26.7 | I13: =VLOOKUP('master table'!B13,Table7[#All], 2,FALSE) -> 3.1 | J13: =VLOOKUP('master table'!B13,Table8[#All], 2,FALSE) -> 72.3 | K13: =VLOOKUP('master table'!B13,Table9[#All], 2,FALSE) -> 165.08 | L13: =VLOOKUP('master table'!B13,Table9[#All], 3,FALSE) -> 152.38 | M13: =VLOOKUP('master table'!B13,Table10[#All], 2,FALSE) -> 5453
B14: Barbados | C14: =VLOOKUP('master table'!B14,Table1[#All], 2,FALSE) -> 1.6 | D14: =VLOOKUP('master table'!B14,Table2[#All], 2,FALSE) -> 31.2 | E14: =VLOOKUP('master table'!B14,Table3[#All], 2,FALSE) -> 0.4 | F14: =VLOOKUP('master table'!B14,Table4[#All], 2,FALSE) -> 0.94 | G14: =VLOOKUP('master table'!B14,Table5[#All], 2,FALSE) -> 0.5 | H14: =VLOOKUP('master table'!B14,Table6[#All], 2,FALSE) -> 38.6 | I14: =VLOOKUP('master table'!B14,Table7[#All], 2,FALSE) -> 88.7 | J14: =VLOOKUP('master table'!B14,Table8[#All], 2,FALSE) -> 79.1 | K14: =VLOOKUP('master table'!B14,Table9[#All], 2,FALSE) -> 177.03 | L14: =VLOOKUP('master table'!B14,Table9[#All], 3,FALSE) -> 165.66 | M14: =VLOOKUP('master table'!B14,Table10[#All], 2,FALSE) -> 19364
... B158: Zimbabwe | C158: =VLOOKUP('master table'!B158,Table1[#All], 2,FALSE) -> 3.6 | D158: =VLOOKUP('master table'!B158,Table2[#All], 2,FALSE) -> 32.2 | E158: =VLOOKUP('master table'!B158,Table3[#All], 2,FALSE) -> 19.1 | F158: =VLOOKUP('master table'!B158,Table4[#All], 2,FALSE) -> 0.96 | G158: =VLOOKUP('master table'!B158,Table5[#All], 2,FALSE) -> 2.7 | H158: =VLOOKUP('master table'!B158,Table6[#All], 2,FALSE) -> 20 | I158: =VLOOKUP('master table'!B158,Table7[#All], 2,FALSE) -> 15.2 | J158: =VLOOKUP('master table'!B158,Table8[#All], 2,FALSE) -> 61.2 | K158: =VLOOKUP('master table'!B158,Table9[#All], 2,FALSE) -> 170.69 | L158: =VLOOKUP('master table'!B158,Table9[#All], 3,FALSE) -> 159.85 | M158: =VLOOKUP('master table'!B158,Table10[#All], 2,FALSE) -> 2778
B159: =SUBTOTAL(103,Table11[Country]) -> 156
